Workbook

Sheet F1
A1: Brand | B1: Logo Brand (nome file immagine) Dim.: 500 x 150 pixel | C1: Tipologia | D1: Serie | E1: Foto serie (nome file immagine) Dim.: 500 x 250 pixel | F1: Modello | G1: Foto modello (nome file immagine) Dim.: 500 x 250 pixel | H1: Descrizione
A2: CLEVER | B2: clever24.jpg | C2: Van 5,40m tetto h2 | D2: Drive Line | F2: Drive 540 Fiat | H2: da 51.499€
A3: CLEVER | B3: clever24.jpg | C3: Van 5,40m tetto h2 | D3: Drive Line | F3: Drive 540 Citroen | H3: da 51.499€
A4: CLEVER | B4: clever24.jpg | C4: Van 5,99m tetto h2 | D4: Drive Line | F4: Drive 600 Fiat | H4: da 52.799€
A5: CLEVER | B5: clever24.jpg | C5: Van 5,99m tetto h2 | D5: Drive Line | F5: Drive 600 Citroen | H5: da 52.799€
A6: CLEVER | B6: clever24.jpg | C6: Van 5,99m tetto h2 | D6: Drive Line | F6: Drive 600 Kids Fiat | H6: da 53.299€
A7: CLEVER | B7: clever24.jpg | C7: Van 5,99m tetto h2 | D7: Drive Line | F7: Drive 600 Kids Citroen | H7: da 53.299€
A8: CLEVER | B8: clever24.jpg | C8: Van 5,40m tetto h2 | D8: Drive Line | F8: Duo 540 Fiat | H8: da 49.999€
A9: CLEVER | B9: clever24.jpg | C9: Van 5,40m tetto h2 | D9: Drive Line | F9: Duo 540 Citroen | H9: da 49.999€
A10: CLEVER | B10: clever24.jpg | C10: Van 5,99m tetto h2 | D10: Drive Line | F10: Duo 600 Fiat | H10: da 51.499€
A11: CLEVER | B11: clever24.jpg | C11: Van 5,99m tetto h2 | D11: Drive Line | F11: Duo 600 Citroen | H11: da 51.499€
A12: CLEVER | B12: clever24.jpg | C12: Van 5,40m tetto h2 | D12: Select Line | F12: Tour 540 Fiat | H12: da 57.299€
A13: CLEVER | B13: clever24.jpg | C13: Van 5,40m tetto h2 | D13: Select Line | F13: Tour 540 Citroen | H13: da 57.299€
... A22: CLEVER | B22: clever24.jpg | C22: Van 5,93m Mercedes Sprinter | D22: Ultima Line | F22: Aventuro 600 Mercedes | H22: da 98.999€

Sheet F2
A1: VEICOLI | B1: =F1!F2 -> Drive 540 Fiat | C1: =F1!F3 -> Drive 540 Citroen | D1: =F1!F4 -> Drive 600 Fiat | E1: =F1!F5 -> Drive 600 Citroen | F1: =F1!F6 -> Drive 600 Kids Fiat | G1: =F1!F7 -> Drive 600 Kids Citroen | H1: =F1!F8 -> Duo 540 Fiat | I1: =F1!F9 -> Duo 540 Citroen | J1: =F1!F10 -> Duo 600 Fiat | K1: =F1!F11 -> Duo 600 Citroen | L1: =F1!F12 -> Tour 540 Fiat | M1: =F1!F13 -> Tour 540 Citroen | N1: =F1!F14 -> Celebration 600 Fiat | O1: =F1!F15 -> Celebration 600 Citroen | P1: =F1!F16 -> Spirit 600 Fiat | Q1: =F1!F17 -> Spirit 600 Citroen | R1: =F1!F18 -> Runner 636 Fiat | S1: =F1!F19 -> Runner 636 Citroen | T1: =F1!F20 -> Runner 636 Active Fiat | U1: =F1!F21 -> Runner 636 Active Citroen | V1: =F1!F22 -> Aventuro 600 Mercedes
A2: MECCANICHE
A3: Fiat Ducato 35 Light 2.2 140 CV cambio manuale | B3: 51499 | D3: 52799 | F3: 53299 | H3: 49999 | J3: 51499 | L3: 57299 | N3: 57999 | P3: 58499 | R3: 59999 | T3: 61999
A4: Citroen Jumper 35 Light 2.2 140 CV cambio manuale | C4: 51499 | E4: 52799 | G4: 53299 | I4: 49999 | K4: 51499 | M4: 57299 | O4: 57999 | Q4: 58499 | S4: 59999 | U4: 61999
A5: Mercedes Sprinter 319 CDI 190 CV 3,5t cambio automatico | V5: 98999
A6: ACCESSORI
A7: Messa in strada e trasporto | B7: 2500 | C7: 2500 | D7: 2500 | E7: 2500 | F7: 2500 | G7: 2500 | H7: 2500 | I7: 2500 | J7: 2500 | K7: 2500 | L7: 2500 | M7: 2500 | N7: 2500 | O7: 2500 | P7: 2500 | Q7: 2500 | R7: 2500 | S7: 2500 | T7: 2500 | U7: 2500 | V7: 2500
A8: *Cambio automatico AT8 (140 CV) | B8: 3759 | C8: 3759 | D8: 3759 | E8: 3759 | F8: 3759 | G8: 3759 | H8: 3759 | I8: 3759 | J8: 3759 | K8: 3759 | L8: 3759 | M8: 3759 | N8: 3759 | O8: 3759 | P8: 3759 | Q8: 3759 | R8: 3759 | S8: 3759 | T8: 3759 | U8: 3759
A9: *Motore 2.2 180 CV con cambio automatico AT8 | B9: 5849 | C9: 5849 | D9: 5849 | E9: 5849 | F9: 5849 | G9: 5849 | H9: 5849 | I9: 5849 | J9: 5849 | K9: 5849 | L9: 5849 | M9: 5849 | N9: 5849 | O9: 5849 | P9: 5849 | Q9: 5849 | R9: 5849 | S9: 5849 | T9: 5849 | U9: 5849
A10: *Telaio Maxi (Fiat) / Heavy (Citroen) 3,5t (solo 5,99m e 6,36m) | D10: 419 | E10: 419 | F10: 419 | G10: 419 | J10: 419 | K10: 419 | N10: 419 | O10: 419 | P10: 419 | Q10: 419 | R10: 419 | S10: 419 | T10: 419 | U10: 419
A11: *Colore carrozzeria: Bianco | B11: 0 | C11: 0 | D11: 0 | E11: 0 | F11: 0 | G11: 0 | H11: 0 | I11: 0 | J11: 0 | K11: 0 | L11: 0 | M11: 0 | N11: 0 | O11: 0 | P11: 0 | Q11: 0 | R11: 0 | S11: 0 | T11: 0 | U11: 0
A12: *Colore carrozzeria: Grigio Artense metallizzato | B12: 729 | C12: 729 | D12: 729 | E12: 729 | F12: 729 | G12: 729 | H12: 729 | I12: 729 | J12: 729 | K12: 729 | L12: 729 | M12: 729 | N12: 729 | O12: 729 | P12: 729 | Q12: 729 | R12: 729 | S12: 729 | T12: 729 | U12: 729
A13: *Colore carrozzeria: Grigio Ferro metallizzato | B13: 729 | C13: 729 | D13: 729 | E13: 729 | F13: 729 | G13: 729 | H13: 729 | I13: 729 | J13: 729 | K13: 729 | L13: 729 | M13: 729 | N13: 729 | O13: 729 | P13: 729 | Q13: 729 | R13: 729 | S13: 729 | T13: 729 | U13: 729
A14: *Colore carrozzeria: Nero metallizzato (Citroen Grigio Grafite) | B14: 729 | C14: 729 | D14: 729 | E14: 729 | F14: 729 | G14: 729 | H14: 729 | I14: 729 | J14: 729 | K14: 729 | L14: 729 | M14: 729 | N14: 729 | O14: 729 | P14: 729 | Q14: 729 | R14: 729 | S14: 729 | T14: 729 | U14: 729
A15: *Colore carrozzeria: Grigio Campovolo | B15: 629 | D15: 629 | F15: 629 | H15: 629 | J15: 629 | L15: 629 | N15: 629 | P15: 629 | R15: 629 | T15: 629
A16: *Colore carrozzeria: Grigio Lanzarote | B16: 629 | D16: 629 | F16: 629 | H16: 629 | J16: 629 | L16: 629 | N16: 629 | P16: 629 | R16: 629 | T16: 629
A17: *Colore carrozzeria: Grigio Expedition | C17: 629 | E17: 629 | G17: 629 | I17: 629 | K17: 629 | M17: 629 | O17: 629 | Q17: 629 | S17: 629 | U17: 629
A18: *Colore carrozzeria: Grigio Thunder | C18: 629 | E18: 629 | G18: 629 | I18: 629 | K18: 629 | M18: 629 | O18: 629 | Q18: 629 | S18: 629 | U18: 629
A19: *Colore carrozzeria: Bianco artico | V19: 0
A20: *Colore carrozzeria: Grigio blu | V20: 0
A21: *Colore carrozzeria: Grigio argento | V21: 0
A22: *Colore carrozzeria: Blu Cavansite metallizzato | V22: 2479
A23: *Colore carrozzeria: Argento Hightech metallizzato | V23: 2479
A24: *Colore carrozzeria: Nero Ossidiana metallizzato | V24: 2479
A25: *Colore carrozzeria: Grigio Selenite metallizzato | V25: 2479
A26: *Colore carrozzeria: Grigio Tenorite | V26: 2479
A27: *Colore carrozzeria: Grigio Muschio | V27: 2479
A28: *Pacchetto Premium Citroen | C28: 2609 | E28: 2609 | G28: 2609 | I28: 2609 | K28: 2609 | M28: 2609 | O28: 2609 | Q28: 2609 | S28: 2609 | U28: 2609
A29: *Cruise control adattivo con pacchetto Safety | B29: 569 | D29: 569 | F29: 569 | H29: 569 | J29: 569 | L29: 569 | N29: 569 | P29: 569 | R29: 569 | T29: 569
A30: *Retrocamera originale | B30: 339 | D30: 339 | F30: 339 | H30: 339 | J30: 339 | L30: 339 | N30: 339 | P30: 339 | R30: 339 | T30: 339
A31: *Fendinebbia con paraurti anteriore verniciato | B31: 629 | D31: 629 | F31: 629 | H31: 629 | J31: 629 | L31: 629 | N31: 629 | P31: 629 | R31: 629
A32: *Fendinebbia con allargamento passaruota | T32: 629
A33: *Pacchetto Lounge | B33: 1399 | D33: 1399 | F33: 1399 | H33: 1399 | J33: 1399 | L33: 1399 | N33: 1399 | P33: 1399 | R33: 1399 | T33: 1399
A34: *Pacchetto Lounge con radio 10 pollici e navigatore | B34: 1039 | D34: 1039 | F34: 1039 | H34: 1039 | J34: 1039 | L34: 1039 | N34: 1039 | P34: 1039 | R34: 1039 | T34: 1039
A35: *Pacchetto Bicolor | B35: 1039 | D35: 1039 | F35: 1039 | H35: 1039 | J35: 1039
A36: *Assale posteriore a doppia balestra | B36: 159 | C36: 159 | D36: 159 | E36: 159 | F36: 159 | G36: 159 | H36: 159 | I36: 159 | J36: 159 | K36: 159 | L36: 159 | M36: 159 | N36: 159 | O36: 159 | P36: 159 | Q36: 159 | R36: 159 | S36: 159 | T36: 159 | U36: 159
A37: *Freno di stazionamento elettrico | B37: 549 | C37: 549 | D37: 549 | E37: 549 | F37: 549 | G37: 549 | H37: 549 | I37: 549 | J37: 549 | K37: 549 | L37: 549 | M37: 549 | N37: 549 | O37: 549 | P37: 549 | Q37: 549 | R37: 549 | S37: 549 | T37: 549 | U37: 549
A38: *Parabrezza riscaldato | B38: 519 | C38: 519 | D38: 519 | E38: 519 | F38: 519 | G38: 519 | H38: 519 | I38: 519 | J38: 519 | K38: 519 | L38: 519 | M38: 519 | N38: 519 | O38: 519 | P38: 519 | Q38: 519 | R38: 519 | S38: 519 | T38: 519 | U38: 519
A39: *Fari full LED | B39: 1039 | C39: 1039 | D39: 1039 | E39: 1039 | F39: 1039 | G39: 1039 | H39: 1039 | I39: 1039 | J39: 1039 | K39: 1039 | L39: 1039 | M39: 1039 | N39: 1039 | O39: 1039 | P39: 1039 | Q39: 1039 | R39: 1039 | S39: 1039 | T39: 1039 | U39: 1039
A40: *Pacchetto Vision livello 1 | B40: 259 | C40: 259 | D40: 259 | E40: 259 | F40: 259 | G40: 259 | H40: 259 | I40: 259 | J40: 259 | K40: 259 | L40: 259 | M40: 259 | N40: 259 | O40: 259 | P40: 259 | Q40: 259 | R40: 259 | S40: 259 | T40: 259 | U40: 259
...
